2025-08-25 12:27:25,642 | INFO | app.main | Iniciando carga...
2025-08-25 12:27:25,642 | INFO | app.main | Carregando cadastros de: data\planta-valores.json
2025-08-25 12:27:25,643 | ERROR | app.main | Falha na execução: Error processing data\planta-valores.json: No content found in JSON file
Traceback (most recent call last):
  File "C:\Users\Tributech\Downloads\Escriptes\aux-clevelandia\aux-clevelandia\app\loader.py", line 96, in processar_cadastros
    raise ValueError("No content found in JSON file")
ValueError: No content found in JSON file

During handling of the above exception, another exception occurred:

Traceback (most recent call last):
  File "C:\Users\Tributech\Downloads\Escriptes\aux-clevelandia\aux-clevelandia\app\main.py", line 199, in main
    cadastro_loader(session, args.json)
    ~~~~~~~~~~~~~~~^^^^^^^^^^^^^^^^^^^^
  File "C:\Users\Tributech\Downloads\Escriptes\aux-clevelandia\aux-clevelandia\app\loader.py", line 103, in processar_cadastros
    raise ValueError(f"Error processing {json_path}: {str(e)}")
ValueError: Error processing data\planta-valores.json: No content found in JSON file
2025-08-25 12:27:25,645 | INFO | app.main | Finalizado em 0.00s.
