2025-08-25 10:44:34,151 | INFO | app.main | Iniciando carga...
2025-08-25 10:44:34,152 | INFO | app.main | Carregando cadastros de: data/bairros.json
2025-08-25 10:44:34,465 | ERROR | app.main | Falha na execução: Error processing data/bairros.json: (psycopg.OperationalError) connection failed: connection to server at "127.0.0.1", port 5432 failed: FATAL:  autentica��o do tipo senha falhou para o usu�rio "postgres"
Multiple connection attempts failed. All failures were:
- host: 'localhost', port: 5432, hostaddr: '::1': connection failed: connection to server at "::1", port 5432 failed: FATAL:  autentica��o do tipo senha falhou para o usu�rio "postgres"
- host: 'localhost', port: 5432, hostaddr: '127.0.0.1': connection failed: connection to server at "127.0.0.1", port 5432 failed: FATAL:  autentica��o do tipo senha falhou para o usu�rio "postgres"
(Background on this error at: https://sqlalche.me/e/20/e3q8)
Traceback (most recent call last):
  File "C:\Users\Tributech\Downloads\Escriptes\aux-clevelandia\venv\Lib\site-packages\sqlalchemy\engine\base.py", line 143, in __init__
    self._dbapi_connection = engine.raw_connection()
                             ~~~~~~~~~~~~~~~~~~~~~^^
  File "C:\Users\Tributech\Downloads\Escriptes\aux-clevelandia\venv\Lib\site-packages\sqlalchemy\engine\base.py", line 3301, in raw_connection
    return self.pool.connect()
           ~~~~~~~~~~~~~~~~~^^
  File "C:\Users\Tributech\Downloads\Escriptes\aux-clevelandia\venv\Lib\site-packages\sqlalchemy\pool\base.py", line 447, in connect
    return _ConnectionFairy._checkout(self)
           ~~~~~~~~~~~~~~~~~~~~~~~~~~^^^^^^
  File "C:\Users\Tributech\Downloads\Escriptes\aux-clevelandia\venv\Lib\site-packages\sqlalchemy\pool\base.py", line 1264, in _checkout
    fairy = _ConnectionRecord.checkout(pool)
  File "C:\Users\Tributech\Downloads\Escriptes\aux-clevelandia\venv\Lib\site-packages\sqlalchemy\pool\base.py", line 711, in checkout
    rec = pool._do_get()
  File "C:\Users\Tributech\Downloads\Escriptes\aux-clevelandia\venv\Lib\site-packages\sqlalchemy\pool\impl.py", line 177, in _do_get
    with util.safe_reraise():
         ~~~~~~~~~~~~~~~~~^^
  File "C:\Users\Tributech\Downloads\Escriptes\aux-clevelandia\venv\Lib\site-packages\sqlalchemy\util\langhelpers.py", line 224, in __exit__
    raise exc_value.with_traceback(exc_tb)
  File "C:\Users\Tributech\Downloads\Escriptes\aux-clevelandia\venv\Lib\site-packages\sqlalchemy\pool\impl.py", line 175, in _do_get
    return self._create_connection()
           ~~~~~~~~~~~~~~~~~~~~~~~^^
  File "C:\Users\Tributech\Downloads\Escriptes\aux-clevelandia\venv\Lib\site-packages\sqlalchemy\pool\base.py", line 388, in _create_connection
    return _ConnectionRecord(self)
  File "C:\Users\Tributech\Downloads\Escriptes\aux-clevelandia\venv\Lib\site-packages\sqlalchemy\pool\base.py", line 673, in __init__
    self.__connect()
    ~~~~~~~~~~~~~~^^
  File "C:\Users\Tributech\Downloads\Escriptes\aux-clevelandia\venv\Lib\site-packages\sqlalchemy\pool\base.py", line 899, in __connect
    with util.safe_reraise():
         ~~~~~~~~~~~~~~~~~^^
  File "C:\Users\Tributech\Downloads\Escriptes\aux-clevelandia\venv\Lib\site-packages\sqlalchemy\util\langhelpers.py", line 224, in __exit__
    raise exc_value.with_traceback(exc_tb)
  File "C:\Users\Tributech\Downloads\Escriptes\aux-clevelandia\venv\Lib\site-packages\sqlalchemy\pool\base.py", line 895, in __connect
    self.dbapi_connection = connection = pool._invoke_creator(self)
                                         ~~~~~~~~~~~~~~~~~~~~^^^^^^
  File "C:\Users\Tributech\Downloads\Escriptes\aux-clevelandia\venv\Lib\site-packages\sqlalchemy\engine\create.py", line 661, in connect
    return dialect.connect(*cargs, **cparams)
           ~~~~~~~~~~~~~~~^^^^^^^^^^^^^^^^^^^
  File "C:\Users\Tributech\Downloads\Escriptes\aux-clevelandia\venv\Lib\site-packages\sqlalchemy\engine\default.py", line 629, in connect
    return self.loaded_dbapi.connect(*cargs, **cparams)  # type: ignore[no-any-return]  # NOQA: E501
           ~~~~~~~~~~~~~~~~~~~~~~~~~^^^^^^^^^^^^^^^^^^^
  File "C:\Users\Tributech\Downloads\Escriptes\aux-clevelandia\venv\Lib\site-packages\psycopg\connection.py", line 125, in connect
    raise type(last_ex)("\n".join(lines)).with_traceback(None)
psycopg.OperationalError: connection failed: connection to server at "127.0.0.1", port 5432 failed: FATAL:  autentica��o do tipo senha falhou para o usu�rio "postgres"
Multiple connection attempts failed. All failures were:
- host: 'localhost', port: 5432, hostaddr: '::1': connection failed: connection to server at "::1", port 5432 failed: FATAL:  autentica��o do tipo senha falhou para o usu�rio "postgres"
- host: 'localhost', port: 5432, hostaddr: '127.0.0.1': connection failed: connection to server at "127.0.0.1", port 5432 failed: FATAL:  autentica��o do tipo senha falhou para o usu�rio "postgres"

The above exception was the direct cause of the following exception:

Traceback (most recent call last):
  File "C:\Users\Tributech\Downloads\Escriptes\aux-clevelandia\aux-clevelandia\app\loader.py", line 86, in processar_cadastros
    loader(sess, json_path)
    ~~~~~~^^^^^^^^^^^^^^^^^
  File "C:\Users\Tributech\Downloads\Escriptes\aux-clevelandia\aux-clevelandia\app\loader_bairro.py", line 136, in processar_cadastros
    ok, skipped = load_from_iterable(records)
                  ~~~~~~~~~~~~~~~~~~^^^^^^^^^
  File "C:\Users\Tributech\Downloads\Escriptes\aux-clevelandia\aux-clevelandia\app\loader_bairro.py", line 88, in load_from_iterable
    check_schema(engine, SETTINGS.schema)
    ~~~~~~~~~~~~^^^^^^^^^^^^^^^^^^^^^^^^^
  File "C:\Users\Tributech\Downloads\Escriptes\aux-clevelandia\aux-clevelandia\app\database.py", line 54, in check_schema
    with engine.connect() as conn:
         ~~~~~~~~~~~~~~^^
  File "C:\Users\Tributech\Downloads\Escriptes\aux-clevelandia\venv\Lib\site-packages\sqlalchemy\engine\base.py", line 3277, in connect
    return self._connection_cls(self)
           ~~~~~~~~~~~~~~~~~~~~^^^^^^
  File "C:\Users\Tributech\Downloads\Escriptes\aux-clevelandia\venv\Lib\site-packages\sqlalchemy\engine\base.py", line 145, in __init__
    Connection._handle_dbapi_exception_noconnection(
    ~~~~~~~~~~~~~~~~~~~~~~~~~~~~~~~~~~~~~~~~~~~~~~~^
        err, dialect, engine
        ^^^^^^^^^^^^^^^^^^^^
    )
    ^
  File "C:\Users\Tributech\Downloads\Escriptes\aux-clevelandia\venv\Lib\site-packages\sqlalchemy\engine\base.py", line 2440, in _handle_dbapi_exception_noconnection
    raise sqlalchemy_exception.with_traceback(exc_info[2]) from e
  File "C:\Users\Tributech\Downloads\Escriptes\aux-clevelandia\venv\Lib\site-packages\sqlalchemy\engine\base.py", line 143, in __init__
    self._dbapi_connection = engine.raw_connection()
                             ~~~~~~~~~~~~~~~~~~~~~^^
  File "C:\Users\Tributech\Downloads\Escriptes\aux-clevelandia\venv\Lib\site-packages\sqlalchemy\engine\base.py", line 3301, in raw_connection
    return self.pool.connect()
           ~~~~~~~~~~~~~~~~~^^
  File "C:\Users\Tributech\Downloads\Escriptes\aux-clevelandia\venv\Lib\site-packages\sqlalchemy\pool\base.py", line 447, in connect
    return _ConnectionFairy._checkout(self)
           ~~~~~~~~~~~~~~~~~~~~~~~~~~^^^^^^
  File "C:\Users\Tributech\Downloads\Escriptes\aux-clevelandia\venv\Lib\site-packages\sqlalchemy\pool\base.py", line 1264, in _checkout
    fairy = _ConnectionRecord.checkout(pool)
  File "C:\Users\Tributech\Downloads\Escriptes\aux-clevelandia\venv\Lib\site-packages\sqlalchemy\pool\base.py", line 711, in checkout
    rec = pool._do_get()
  File "C:\Users\Tributech\Downloads\Escriptes\aux-clevelandia\venv\Lib\site-packages\sqlalchemy\pool\impl.py", line 177, in _do_get
    with util.safe_reraise():
         ~~~~~~~~~~~~~~~~~^^
  File "C:\Users\Tributech\Downloads\Escriptes\aux-clevelandia\venv\Lib\site-packages\sqlalchemy\util\langhelpers.py", line 224, in __exit__
    raise exc_value.with_traceback(exc_tb)
  File "C:\Users\Tributech\Downloads\Escriptes\aux-clevelandia\venv\Lib\site-packages\sqlalchemy\pool\impl.py", line 175, in _do_get
    return self._create_connection()
           ~~~~~~~~~~~~~~~~~~~~~~~^^
  File "C:\Users\Tributech\Downloads\Escriptes\aux-clevelandia\venv\Lib\site-packages\sqlalchemy\pool\base.py", line 388, in _create_connection
    return _ConnectionRecord(self)
  File "C:\Users\Tributech\Downloads\Escriptes\aux-clevelandia\venv\Lib\site-packages\sqlalchemy\pool\base.py", line 673, in __init__
    self.__connect()
    ~~~~~~~~~~~~~~^^
  File "C:\Users\Tributech\Downloads\Escriptes\aux-clevelandia\venv\Lib\site-packages\sqlalchemy\pool\base.py", line 899, in __connect
    with util.safe_reraise():
         ~~~~~~~~~~~~~~~~~^^
  File "C:\Users\Tributech\Downloads\Escriptes\aux-clevelandia\venv\Lib\site-packages\sqlalchemy\util\langhelpers.py", line 224, in __exit__
    raise exc_value.with_traceback(exc_tb)
  File "C:\Users\Tributech\Downloads\Escriptes\aux-clevelandia\venv\Lib\site-packages\sqlalchemy\pool\base.py", line 895, in __connect
    self.dbapi_connection = connection = pool._invoke_creator(self)
                                         ~~~~~~~~~~~~~~~~~~~~^^^^^^
  File "C:\Users\Tributech\Downloads\Escriptes\aux-clevelandia\venv\Lib\site-packages\sqlalchemy\engine\create.py", line 661, in connect
    return dialect.connect(*cargs, **cparams)
           ~~~~~~~~~~~~~~~^^^^^^^^^^^^^^^^^^^
  File "C:\Users\Tributech\Downloads\Escriptes\aux-clevelandia\venv\Lib\site-packages\sqlalchemy\engine\default.py", line 629, in connect
    return self.loaded_dbapi.connect(*cargs, **cparams)  # type: ignore[no-any-return]  # NOQA: E501
           ~~~~~~~~~~~~~~~~~~~~~~~~~^^^^^^^^^^^^^^^^^^^
  File "C:\Users\Tributech\Downloads\Escriptes\aux-clevelandia\venv\Lib\site-packages\psycopg\connection.py", line 125, in connect
    raise type(last_ex)("\n".join(lines)).with_traceback(None)
sqlalchemy.exc.OperationalError: (psycopg.OperationalError) connection failed: connection to server at "127.0.0.1", port 5432 failed: FATAL:  autentica��o do tipo senha falhou para o usu�rio "postgres"
Multiple connection attempts failed. All failures were:
- host: 'localhost', port: 5432, hostaddr: '::1': connection failed: connection to server at "::1", port 5432 failed: FATAL:  autentica��o do tipo senha falhou para o usu�rio "postgres"
- host: 'localhost', port: 5432, hostaddr: '127.0.0.1': connection failed: connection to server at "127.0.0.1", port 5432 failed: FATAL:  autentica��o do tipo senha falhou para o usu�rio "postgres"
(Background on this error at: https://sqlalche.me/e/20/e3q8)

During handling of the above exception, another exception occurred:

Traceback (most recent call last):
  File "C:\Users\Tributech\Downloads\Escriptes\aux-clevelandia\aux-clevelandia\app\main.py", line 199, in main
    cadastro_loader(session, args.json)
    ~~~~~~~~~~~~~~~^^^^^^^^^^^^^^^^^^^^
  File "C:\Users\Tributech\Downloads\Escriptes\aux-clevelandia\aux-clevelandia\app\loader.py", line 96, in processar_cadastros
    raise ValueError(f"Error processing {json_path}: {str(e)}")
ValueError: Error processing data/bairros.json: (psycopg.OperationalError) connection failed: connection to server at "127.0.0.1", port 5432 failed: FATAL:  autentica��o do tipo senha falhou para o usu�rio "postgres"
Multiple connection attempts failed. All failures were:
- host: 'localhost', port: 5432, hostaddr: '::1': connection failed: connection to server at "::1", port 5432 failed: FATAL:  autentica��o do tipo senha falhou para o usu�rio "postgres"
- host: 'localhost', port: 5432, hostaddr: '127.0.0.1': connection failed: connection to server at "127.0.0.1", port 5432 failed: FATAL:  autentica��o do tipo senha falhou para o usu�rio "postgres"
(Background on this error at: https://sqlalche.me/e/20/e3q8)
2025-08-25 10:44:34,481 | INFO | app.main | Finalizado em 0.33s.
